# Tratamento de erros

O uso de `try`, `catch`, e `finally` em JavaScript é uma maneira de lidar com erros (ou exceções) que podem ocorrer durante a execução do código. Aqui está uma explicação detalhada de cada um desses blocos:

**Try Block (`try`):**
O bloco `try` é onde você coloca o código que você deseja executar. Este bloco é usado para envolver o código que pode gerar uma exceção. Se ocorrer um erro dentro do bloco `try`, a execução será interrompida e o controle será passado para o bloco `catch` correspondente.

**Catch Block (`catch`):**
O bloco `catch` é usado para lidar com exceções que podem ocorrer dentro do bloco `try`. Se ocorrer um erro dentro do bloco `try`, o código dentro do bloco `catch` será executado. Aqui você pode especificar como lidar com o erro, seja exibindo uma mensagem de erro para o usuário, registrando o erro para análise futura, ou qualquer outra ação apropriada para lidar com a exceção.

**Finally Block (`finally`):**
O bloco `finally` é opcional e é usado para definir código que deve ser executado independentemente de ocorrer ou não uma exceção dentro do bloco `try`. Este bloco é útil para código que precisa ser executado, independentemente do resultado do bloco `try`. Por exemplo, você pode usar o bloco `finally` para liberar recursos, fechar conexões de banco de dados ou executar qualquer limpeza necessária, garantindo que esse código seja sempre executado, mesmo se ocorrer uma exceção.

Aqui está um exemplo simples de como usar `try`, `catch` e `finally` em JavaScript:

```javascript
try {
  // Código que pode gerar uma exceção
  console.log("Este código está dentro do bloco try.");
  // Gerar um erro
  throw new Error("Isso é um erro!");
} catch (error) {
  // Lidar com o erro
  console.error("Ocorreu um erro:", error.message);
} finally {
  // Este bloco será sempre executado, independentemente de ocorrer uma exceção ou não
  console.log("Este código está dentro do bloco finally.");
}

// Saída:
// Este código está dentro do bloco try.
// Ocorreu um erro: Isso é um erro!
// Este código está dentro do bloco finally.
```

Neste exemplo, o código dentro do bloco `try` gera um erro utilizando o comando `throw new Error()`. Como resultado, o controle é passado para o bloco `catch`, onde o erro é tratado e uma mensagem é exibida. Em seguida, o código dentro do bloco `finally` é executado, independentemente do ocorrido anteriormente.
